2025-07-29 17:05:29,799 - ERROR - Future exception was never retrieved
future: <Future finished exception=OperationFailure("bad auth : authentication failed, full error: {'ok': 0, 'errmsg': 'bad auth : authentication failed', 'code': 8000, 'codeName': 'AtlasError'}")>
Traceback (most recent call last):
  File "C:\Users\SVCS\anaconda3\envs\Python_3.13\Lib\concurrent\futures\thread.py", line 59, in run
    result = self.fn(*self.args, **self.kwargs)
  File "C:\Users\SVCS\anaconda3\envs\Python_3.13\Lib\site-packages\pymongo\synchronous\collection.py", line 2378, in create_index
    return (self._create_indexes([index], session, **cmd_options))[0]
            ~~~~~~~~~~~~~~~~~~~~^^^^^^^^^^^^^^^^^^^^^^^^^^^^^^^^^
  File "C:\Users\SVCS\anaconda3\envs\Python_3.13\Lib\site-packages\pymongo\_csot.py", line 125, in csot_wrapper
    return func(self, *args, **kwargs)
  File "C:\Users\SVCS\anaconda3\envs\Python_3.13\Lib\site-packages\pymongo\synchronous\collection.py", line 2231, in _create_indexes
    with self._conn_for_writes(session, operation=_Op.CREATE_INDEXES) as conn:
         ~~~~~~~~~~~~~~~~~~~~~^^^^^^^^^^^^^^^^^^^^^^^^^^^^^^^^^^^^^^^
  File "C:\Users\SVCS\anaconda3\envs\Python_3.13\Lib\contextlib.py", line 141, in __enter__
    return next(self.gen)
  File "C:\Users\SVCS\anaconda3\envs\Python_3.13\Lib\site-packages\pymongo\synchronous\mongo_client.py", line 1756, in _checkout
    with server.checkout(handler=err_handler) as conn:
         ~~~~~~~~~~~~~~~^^^^^^^^^^^^^^^^^^^^^
  File "C:\Users\SVCS\anaconda3\envs\Python_3.13\Lib\contextlib.py", line 141, in __enter__
    return next(self.gen)
  File "C:\Users\SVCS\anaconda3\envs\Python_3.13\Lib\site-packages\pymongo\synchronous\pool.py", line 1119, in checkout
    conn = self._get_conn(checkout_started_time, handler=handler)
  File "C:\Users\SVCS\anaconda3\envs\Python_3.13\Lib\site-packages\pymongo\synchronous\pool.py", line 1281, in _get_conn
    conn = self.connect(handler=handler)
  File "C:\Users\SVCS\anaconda3\envs\Python_3.13\Lib\site-packages\pymongo\synchronous\pool.py", line 1073, in connect
    conn.authenticate()
    ~~~~~~~~~~~~~~~~~^^
  File "C:\Users\SVCS\anaconda3\envs\Python_3.13\Lib\site-packages\pymongo\synchronous\pool.py", line 526, in authenticate
    auth.authenticate(creds, self, reauthenticate=reauthenticate)
    ~~~~~~~~~~~~~~~~~^^^^^^^^^^^^^^^^^^^^^^^^^^^^^^^^^^^^^^^^^^^^
  File "C:\Users\SVCS\anaconda3\envs\Python_3.13\Lib\site-packages\pymongo\synchronous\auth.py", line 450, in authenticate
    auth_func(credentials, conn)
    ~~~~~~~~~^^^^^^^^^^^^^^^^^^^
  File "C:\Users\SVCS\anaconda3\envs\Python_3.13\Lib\site-packages\pymongo\synchronous\auth.py", line 355, in _authenticate_default
    return _authenticate_scram(credentials, conn, "SCRAM-SHA-1")
  File "C:\Users\SVCS\anaconda3\envs\Python_3.13\Lib\site-packages\pymongo\synchronous\auth.py", line 135, in _authenticate_scram
    res = conn.command(source, cmd)
  File "C:\Users\SVCS\anaconda3\envs\Python_3.13\Lib\site-packages\pymongo\synchronous\helpers.py", line 47, in inner
    return func(*args, **kwargs)
  File "C:\Users\SVCS\anaconda3\envs\Python_3.13\Lib\site-packages\pymongo\synchronous\pool.py", line 414, in command
    return command(
        self,
    ...<20 lines>...
        write_concern=write_concern,
    )
  File "C:\Users\SVCS\anaconda3\envs\Python_3.13\Lib\site-packages\pymongo\synchronous\network.py", line 212, in command
    helpers_shared._check_command_response(
    ~~~~~~~~~~~~~~~~~~~~~~~~~~~~~~~~~~~~~~^
        response_doc,
        ^^^^^^^^^^^^^
    ...<2 lines>...
        parse_write_concern_error=parse_write_concern_error,
        ^^^^^^^^^^^^^^^^^^^^^^^^^^^^^^^^^^^^^^^^^^^^^^^^^^^^
    )
    ^
  File "C:\Users\SVCS\anaconda3\envs\Python_3.13\Lib\site-packages\pymongo\helpers_shared.py", line 250, in _check_command_response
    raise OperationFailure(errmsg, code, response, max_wire_version)
pymongo.errors.OperationFailure: bad auth : authentication failed, full error: {'ok': 0, 'errmsg': 'bad auth : authentication failed', 'code': 8000, 'codeName': 'AtlasError'}
2025-07-29 17:08:14,533 - INFO - Received registration request for venky@gmail.com,7437542301
2025-07-29 17:08:50,020 - INFO - Received registration request for venky@gmail.com,7437542301
2025-07-29 17:09:43,698 - INFO - Received registration request for venky@gmail.com,7437542301
2025-07-29 17:12:03,827 - INFO - Received registration request for venky@gmail.com,7437542301
2025-07-29 17:12:04,006 - WARNING - (trapped) error reading bcrypt version
Traceback (most recent call last):
  File "C:\Users\SVCS\anaconda3\envs\Python_3.13\Lib\site-packages\passlib\handlers\bcrypt.py", line 620, in _load_backend_mixin
    version = _bcrypt.__about__.__version__
              ^^^^^^^^^^^^^^^^^
AttributeError: module 'bcrypt' has no attribute '__about__'
2025-07-29 17:12:04,562 - INFO - User venky@gmail.com,7437542301 registered successfully.
2025-07-29 17:12:04,562 - INFO - register_user executed in 735 ms
2025-07-29 17:17:37,571 - INFO - Received registration request for venky@gmail.com,7437542301
2025-07-29 17:17:37,625 - WARNING - Duplicate registration attempt: venky@gmail.com or 7437542301
2025-07-29 17:17:41,441 - INFO - Received registration request for venky@gmail.com,7437542301
2025-07-29 17:17:41,497 - WARNING - Duplicate registration attempt: venky@gmail.com or 7437542301
2025-07-29 17:17:43,416 - INFO - Received registration request for venky@gmail.com,7437542301
2025-07-29 17:17:43,464 - WARNING - Duplicate registration attempt: venky@gmail.com or 7437542301
2025-07-29 17:20:46,486 - INFO - Received registration request for vamsi@gmail.com,7437542301
2025-07-29 17:20:46,538 - WARNING - Duplicate registration attempt: vamsi@gmail.com or 7437542301
2025-07-29 19:51:27,913 - WARNING - Login failed: your_username not found.
2025-07-29 19:53:30,718 - WARNING - Login failed: vamsi_kota not found.
2025-07-29 19:54:03,139 - WARNING - Login failed: vamsikota not found.
2025-07-29 19:54:59,019 - WARNING - Login failed: vamsikota not found.
2025-07-29 19:59:35,201 - WARNING - Login failed: vamsikota not found.
2025-07-29 20:35:17,034 - INFO - Received registration request for venky@gmail.com,7437542301
2025-07-29 20:35:17,421 - WARNING - Duplicate registration attempt: venky@gmail.com or 7437542301
2025-07-29 20:36:38,190 - INFO - Received registration request for vamsi@gmail.com,9989103545
2025-07-29 20:36:38,468 - WARNING - (trapped) error reading bcrypt version
Traceback (most recent call last):
  File "C:\Users\SVCS\anaconda3\envs\Python_3.13\Lib\site-packages\passlib\handlers\bcrypt.py", line 620, in _load_backend_mixin
    version = _bcrypt.__about__.__version__
              ^^^^^^^^^^^^^^^^^
AttributeError: module 'bcrypt' has no attribute '__about__'
2025-07-29 20:36:39,351 - INFO - User vamsi@gmail.com,9989103545 registered successfully.
2025-07-29 20:36:39,351 - INFO - register_user executed in 1161 ms
2025-07-29 20:39:18,877 - INFO - User vamsi@gmail.com logged in successfully.
2025-07-29 20:39:18,877 - INFO - login executed in 599 ms
2025-07-29 20:41:03,766 - INFO - [ResetToken] Sent to vamsi@gmail.com (valid 24h): FiCTzG-NJNtxesDndCoKEOi4b6UVguQ0_MphbtwMzB4
2025-07-29 20:41:03,767 - INFO - forgot_password executed in 982 ms
2025-07-29 20:43:33,981 - INFO - User vamsi@gmail.com logged in successfully.
2025-07-29 20:43:33,982 - INFO - login executed in 585 ms
2025-07-29 20:47:28,846 - INFO - User vamsi@gmail.com logged in successfully.
2025-07-29 20:47:28,846 - INFO - login executed in 781 ms
2025-07-29 20:51:28,205 - INFO - User vamsi@gmail.com logged in successfully.
2025-07-29 20:51:28,205 - INFO - login executed in 2318 ms
2025-07-29 20:53:47,003 - INFO - Received registration request for priya@gmail.com,8790316555
2025-07-29 20:53:48,206 - INFO - User priya@gmail.com,8790316555 registered successfully.
2025-07-29 20:53:48,206 - INFO - register_user executed in 1202 ms
2025-07-29 20:54:51,804 - WARNING - Login failed: Incorrect password for priya@gmail.com
2025-07-29 20:55:06,035 - WARNING - Login failed: Incorrect password for priya@gmail.com
2025-07-29 20:55:18,775 - WARNING - Login failed: Incorrect password for priya@gmail.com
2025-07-29 20:55:28,234 - INFO - User priya@gmail.com logged in successfully.
2025-07-29 20:55:28,234 - INFO - login executed in 879 ms
2025-07-29 20:57:30,168 - INFO - logout_user executed in 0 ms
2025-07-29 20:59:49,761 - INFO - User priya@gmail.com logged in successfully.
2025-07-29 20:59:49,761 - INFO - login executed in 1175 ms
2025-07-29 21:01:32,864 - INFO - User priya@gmail.com logged in successfully.
2025-07-29 21:01:32,864 - INFO - login executed in 999 ms
2025-07-29 21:02:26,423 - INFO - User 6888e7839662fb2073502295 requested contact update
2025-07-29 21:02:26,424 - INFO - Checking for existing mobile: 8790316555
2025-07-29 21:02:27,039 - INFO - User 6888e7839662fb2073502295 updated contact: {'mobile': '8790316555'}
2025-07-29 21:02:27,039 - INFO - change_contact executed in 616 ms
